<mujoco model="iiwa14">
    <compiler angle="radian" meshdir="../meshes/iiwa14/visual/" />
    <size njmax="500" nconmax="100" />
    <asset>
        <mesh name="link_0" file="link_0.stl" />
        <mesh name="link_1" file="link_1.stl" />
        <mesh name="link_2" file="link_2.stl" />
        <mesh name="link_3" file="link_3.stl" />
        <mesh name="link_4" file="link_4.stl" />
        <mesh name="link_5" file="link_5.stl" />
        <mesh name="link_6" file="link_6.stl" />
        <mesh name="link_7" file="link_7.stl" />
    </asset>
    <worldbody>
        <geom type="mesh" contype="0" conaffinity="0" group="1" rgba="0.4 0.4 0.4 1" mesh="link_0" />
        <geom type="mesh" rgba="0.4 0.4 0.4 1" mesh="link_0" />
        <body name="iiwa_link_1" pos="0 0 0.1575">
            <inertial pos="0 -0.03 0.12" mass="4" diaginertia="0.1 0.09 0.02" />
            <joint name="iiwa_joint_1" pos="0 0 0" axis="0 0 1" limited="true" range="-2.96706 2.96706" damping="0.5" />
            <geom type="mesh" contype="0" conaffinity="0" group="1" rgba="1 0.423529 0.0392157 1" mesh="link_1" />
            <geom type="mesh" rgba="1 0.423529 0.0392157 1" mesh="link_1" />
            <body name="iiwa_link_2" pos="0 0 0.2025" quat="0 0 0.707107 0.707107">
                <inertial pos="0.0003 0.059 0.042" quat="0.707107 0.707107 0 0" mass="4" diaginertia="0.05 0.044 0.018" />
                <joint name="iiwa_joint_2" pos="0 0 0" axis="0 0 1" limited="true" range="-2.0944 2.0944" damping="0.5" />
                <geom type="mesh" contype="0" conaffinity="0" group="1" rgba="1 0.423529 0.0392157 1" mesh="link_2" />
                <geom type="mesh" rgba="1 0.423529 0.0392157 1" mesh="link_2" />
                <body name="iiwa_link_3" pos="0 0.2045 0" quat="0 0 0.707107 0.707107">
                    <inertial pos="0 0.03 0.13" mass="3" diaginertia="0.08 0.075 0.01" />
                    <joint name="iiwa_joint_3" pos="0 0 0" axis="0 0 1" limited="true" range="-2.96706 2.96706" damping="0.5" />
                    <geom type="mesh" contype="0" conaffinity="0" group="1" rgba="1 0.423529 0.0392157 1" mesh="link_3" />
                    <geom type="mesh" rgba="1 0.423529 0.0392157 1" mesh="link_3" />
                    <body name="iiwa_link_4" pos="0 0 0.2155" quat="0.707107 0.707107 0 0">
                        <inertial pos="0 0.067 0.034" quat="0.707107 0.707107 0 0" mass="2.7" diaginertia="0.03 0.029 0.01" />
                        <joint name="iiwa_joint_4" pos="0 0 0" axis="0 0 1" limited="true" range="-2.0944 2.0944" damping="0.5" />
                        <geom type="mesh" contype="0" conaffinity="0" group="1" rgba="1 0.423529 0.0392157 1" mesh="link_4" />
                        <geom type="mesh" rgba="1 0.423529 0.0392157 1" mesh="link_4" />
                        <body name="iiwa_link_5" pos="0 0.1845 0" quat="0 0 0.707107 0.707107">
                            <inertial pos="0.0001 0.021 0.076" mass="1.7" diaginertia="0.02 0.018 0.005" />
                            <joint name="iiwa_joint_5" pos="0 0 0" axis="0 0 1" limited="true" range="-2.96706 2.96706" damping="0.5" />
                            <geom type="mesh" contype="0" conaffinity="0" group="1" rgba="1 0.423529 0.0392157 1" mesh="link_5" />
                            <geom type="mesh" rgba="1 0.423529 0.0392157 1" mesh="link_5" />
                            <body name="iiwa_link_6" pos="0 0 0.2155" quat="0.707107 0.707107 0 0">
                                <inertial pos="0 0.0006 0.0004" quat="0.707107 0.707107 0 0" mass="1.8" diaginertia="0.005 0.0047 0.0036" />
                                <joint name="iiwa_joint_6" pos="0 0 0" axis="0 0 1" limited="true" range="-2.0944 2.0944" damping="0.5" />
                                <geom type="mesh" contype="0" conaffinity="0" group="1" rgba="1 0.423529 0.0392157 1" mesh="link_6" />
                                <geom type="mesh" rgba="1 0.423529 0.0392157 1" mesh="link_6" />
                                <body name="iiwa_link_7" pos="0 0.081 0" quat="0 0 0.707107 0.707107">
                                    <inertial pos="0 0 0.0200001" mass="0.300001" diaginertia="1.001 1.001 1.001" />
                                    <joint name="iiwa_joint_7" pos="0 0 0" axis="0 0 1" limited="true" range="-3.05433 3.05433" damping="0.5" />
                                    <geom type="mesh" contype="0" conaffinity="0" group="1" rgba="0.4 0.4 0.4 1" mesh="link_7" />
                                    <geom type="mesh" rgba="0.4 0.4 0.4 1" mesh="link_7" />
                                </body>
                            </body>
                        </body>
                    </body>
                </body>
            </body>
        </body>
    </worldbody>
    
    <actuator>
  
        <motor name="iiwa_joint_1" gear="100" joint="iiwa_joint_1" />
        <motor name="iiwa_joint_2" gear="100" joint="iiwa_joint_2" />
        <motor name="iiwa_joint_3" gear="100" joint="iiwa_joint_3" />
        <motor name="iiwa_joint_4" gear="100" joint="iiwa_joint_4" />
        <motor name="iiwa_joint_5" gear="100" joint="iiwa_joint_5" />
        <motor name="iiwa_joint_6" gear="100" joint="iiwa_joint_6" />
        <motor name="iiwa_joint_7" gear="100" joint="iiwa_joint_7" />
    </actuator>
</mujoco>
