<?xml version="1.0"?>
<!--|
    Copyright (C) 2019-2022 Learning Algorithms and Systems Laboratory, EPFL, Switzerland
    Authors:  Konstantinos Chatzilygeroudis (maintainer)
              Matthias Mayr
              Bernardo Fichera
    email:    costashatz@gmail.com
              matthias.mayr@cs.lth.se
              bernardo.fichera@epfl.ch
    Other contributors:
              Yoan Mollard (yoan@aubrune.eu)
              Walid Amanhoud (walid.amanhoud@epfl.ch)
    website:  lasa.epfl.ch

    This file is part of iiwa_ros.

    iiwa_ros is free software: you can redistribute it and/or modify
    it under the terms of the GNU General Public License as published by
    the Free Software Foundation, either version 3 of the License, or
    (at your option) any later version.

    iiwa_ros is distributed in the hope that it will be useful,
    but WITHOUT ANY WARRANTY; without even the implied warranty of
    MERCHANTABILITY or FITNESS FOR A PARTICULAR PURPOSE.  See the
    GNU General Public License for more details.

|-->
<robot xmlns:xacro="http://www.ros.org/wiki/xacro">

  <!-- Import all Gazebo-customization elements, including Gazebo colors -->
  <xacro:include filename="$(find iiwa_description)/urdf/iiwa.gazebo.xacro" />
  <!-- Import Transmissions -->
  <xacro:include filename="$(find iiwa_description)/urdf/iiwa.transmission.xacro" />
  <!-- Include Utilities -->
  <xacro:include filename="$(find iiwa_description)/urdf/utilities.xacro" />

  <!-- some parameters -->
  <xacro:property name="safety" value="true"/>

  <!-- some constants -->
  <xacro:property name="safety_controller_k_pos" value="100"/>
  <xacro:property name="safety_controller_k_vel" value="10"/>
  <xacro:property name="safety_percentage" value="0.95"/>
  <xacro:property name="joint_damping" value="0.5"/>
  <!-- joint limits -->
  <xacro:property name="joint_limit_1" value="170"/>
  <xacro:property name="joint_limit_2" value="120"/>
  <xacro:property name="joint_limit_3" value="170"/>
  <xacro:property name="joint_limit_4" value="120"/>
  <xacro:property name="joint_limit_5" value="170"/>
  <xacro:property name="joint_limit_6" value="120"/>
  <xacro:property name="joint_limit_7" value="175"/>
  <!-- max torques per joint -->
  <xacro:property name="max_effort_1" value="320"/>
  <xacro:property name="max_effort_2" value="320"/>
  <xacro:property name="max_effort_3" value="176"/>
  <xacro:property name="max_effort_4" value="176"/>
  <xacro:property name="max_effort_5" value="110"/>
  <xacro:property name="max_effort_6" value="40"/>
  <xacro:property name="max_effort_7" value="40"/>
  <!-- max velocities per joint -->
  <xacro:property name="max_velocity_1" value="${85 * PI / 180.}"/>
  <xacro:property name="max_velocity_2" value="${85 * PI / 180.}"/>
  <xacro:property name="max_velocity_3" value="${100 * PI / 180.}"/>
  <xacro:property name="max_velocity_4" value="${75 * PI/ 180.}"/>
  <xacro:property name="max_velocity_5" value="${130 * PI / 180.}"/>
  <xacro:property name="max_velocity_6" value="${135 * PI / 180.}"/>
  <xacro:property name="max_velocity_7" value="${135 * PI / 180.}"/>

  <xacro:macro name="iiwa14" params="parent hardware_interface  force_sensor grabber collision_postfix *origin">

    <!--joint between {parent} and link_0-->
    <joint name="${parent}_joint" type="fixed">
      <xacro:insert_block name="origin"/>
      <parent link="${parent}"/>
      <child link="link_0"/>
    </joint>

    <link name="link_0">
      <inertial>
        <origin xyz="-0.1 0 0.07" rpy="0 0 0"/>
        <mass value="5"/>
        <inertia ixx="0.05" ixy="0" ixz="0" iyy="0.06" iyz="0" izz="0.03" />
      </inertial>

      <visual>
        <origin xyz="0 0 0" rpy="0 0 0"/>
        <geometry>
          <mesh filename="package://iiwa_description/meshes/iiwa14/visual/link_0.stl"/>
        </geometry>
        <material name="Grey"/>
      </visual>

      <collision>
        <origin xyz="0 0 0" rpy="0 0 0"/>
        <geometry>
          <mesh filename="package://iiwa_description/meshes/iiwa14/collision/link_0${collision_postfix}.stl"/>
        </geometry>
        <material name="Grey"/>
      </collision>

      <self_collision_checking>
        <origin xyz="0 0 0" rpy="0 0 0"/>
        <geometry>
          <capsule radius="0.15" length="0.25"/>
        </geometry>
      </self_collision_checking>

    </link>

    <!-- joint between link_0 and link_1 -->
    <joint name="joint_1" type="revolute">
      <parent link="link_0"/>
      <child link="link_1"/>
      <origin xyz="0 0 0.1575" rpy="0 0 0"/>
      <axis xyz="0 0 1"/>
      <limit lower="${-joint_limit_1 * PI / 180}" upper="${joint_limit_1 * PI / 180}" effort="${max_effort_1}" velocity="${max_velocity_1}" />
      <xacro:safe_controller safety="${safety}" lower="${-safety_percentage * joint_limit_1 * PI / 180}" upper="${safety_percentage * joint_limit_1 * PI / 180}" k_p="${safety_controller_k_pos}" k_v="${safety_controller_k_vel}"/>
      <dynamics damping="${joint_damping}"/>
    </joint>

    <link name="link_1">
      <inertial>
        <origin xyz="0 -0.03 0.12" rpy="0 0 0"/>
        <mass value="4"/>
        <inertia ixx="0.1" ixy="0" ixz="0" iyy="0.09" iyz="0" izz="0.02" />
      </inertial>

      <visual>
        <origin xyz="0 0 0" rpy="0 0 0"/>
        <geometry>
          <mesh filename="package://iiwa_description/meshes/iiwa14/visual/link_1.stl"/>
        </geometry>
        <material name="Orange"/>
      </visual>

      <collision>
        <origin xyz="0 0 0" rpy="0 0 0"/>
        <geometry>
          <mesh filename="package://iiwa_description/meshes/iiwa14/collision/link_1${collision_postfix}.stl"/>
        </geometry>
        <material name="Orange"/>
      </collision>
    </link>

    <!-- joint between link_1 and link_2 -->
    <joint name="joint_2" type="revolute">
      <parent link="link_1"/>
      <child link="link_2"/>
      <origin xyz="0 0 0.2025" rpy="${PI / 2}   0 ${PI}"/>
      <axis xyz="0 0 1"/>
      <limit lower="${-joint_limit_2 * PI / 180}" upper="${joint_limit_2 * PI / 180}" effort="${max_effort_2}" velocity="${max_velocity_2}" />
      <xacro:safe_controller safety="${safety}" lower="${-safety_percentage * joint_limit_2 * PI / 180}" upper="${safety_percentage * joint_limit_2 * PI / 180}" k_p="${safety_controller_k_pos}" k_v="${safety_controller_k_vel}"/>
      <dynamics damping="${joint_damping}"/>
    </joint>

    <link name="link_2">
      <inertial>
        <origin xyz="0.0003 0.059 0.042" rpy="0 0 0"/>
        <mass value="4"/>
        <inertia ixx="0.05" ixy="0" ixz="0" iyy="0.018" iyz="0" izz="0.044" />
      </inertial>

      <visual>
        <origin xyz="0 0 0" rpy="0 0 0"/>
        <geometry>
          <mesh filename="package://iiwa_description/meshes/iiwa14/visual/link_2.stl"/>
        </geometry>
        <material name="Orange"/>
      </visual>

      <collision>
        <origin xyz="0 0 0" rpy="0 0 0"/>
        <geometry>
          <mesh filename="package://iiwa_description/meshes/iiwa14/collision/link_2${collision_postfix}.stl"/>
        </geometry>
        <material name="Orange"/>
      </collision>
    </link>

    <!-- joint between link_2 and link_3 -->
    <joint name="joint_3" type="revolute">
      <parent link="link_2"/>
      <child link="link_3"/>
      <origin xyz="0 0.2045 0" rpy="${PI / 2} 0 ${PI}"/>
      <axis xyz="0 0 1"/>
      <limit lower="${-joint_limit_3 * PI / 180}" upper="${joint_limit_3 * PI / 180}" effort="${max_effort_3}" velocity="${max_velocity_3}" />
      <xacro:safe_controller safety="${safety}" lower="${-safety_percentage * joint_limit_3 * PI / 180}" upper="${safety_percentage * joint_limit_3 * PI / 180}" k_p="${safety_controller_k_pos}" k_v="${safety_controller_k_vel}"/>
      <dynamics damping="${joint_damping}"/>
    </joint>

    <link name="link_3">
      <inertial>
        <origin xyz="0 0.03 0.13" rpy="0 0 0"/>
        <mass value="3"/>
        <inertia ixx="0.08" ixy="0" ixz="0" iyy="0.075" iyz="0" izz="0.01" />
      </inertial>

      <visual>
        <origin xyz="0 0 0" rpy="0 0 0"/>
        <geometry>
          <mesh filename="package://iiwa_description/meshes/iiwa14/visual/link_3.stl"/>
        </geometry>
        <material name="Orange"/>
      </visual>

      <collision>
        <origin xyz="0 0 0" rpy="0 0 0"/>
        <geometry>
          <mesh filename="package://iiwa_description/meshes/iiwa14/collision/link_3${collision_postfix}.stl"/>
        </geometry>
        <material name="Orange"/>
      </collision>
    </link>

    <!-- joint between link_3 and link_4 -->
    <joint name="joint_4" type="revolute">
      <parent link="link_3"/>
      <child link="link_4"/>
      <origin xyz="0 0 0.2155" rpy="${PI / 2} 0 0"/>
      <axis xyz="0 0 1"/>
      <limit lower="${-joint_limit_4 * PI / 180}" upper="${joint_limit_4 * PI / 180}" effort="${max_effort_4}" velocity="${max_velocity_4}" />
      <xacro:safe_controller safety="${safety}" lower="${-safety_percentage * joint_limit_4 * PI / 180}" upper="${safety_percentage * joint_limit_4 * PI / 180}" k_p="${safety_controller_k_pos}" k_v="${safety_controller_k_vel}"/>
      <dynamics damping="${joint_damping}"/>
    </joint>

    <link name="link_4">
      <inertial>
        <origin xyz="0 0.067 0.034" rpy="0 0 0"/>
        <mass value="2.7"/>
        <inertia ixx="0.03" ixy="0" ixz="0" iyy="0.01" iyz="0" izz="0.029" />
      </inertial>

      <visual>
        <origin xyz="0 0 0" rpy="0 0 0"/>
        <geometry>
          <mesh filename="package://iiwa_description/meshes/iiwa14/visual/link_4.stl"/>
        </geometry>
        <material name="Orange"/>
      </visual>

      <collision>
        <origin xyz="0 0 0" rpy="0 0 0"/>
        <geometry>
          <mesh filename="package://iiwa_description/meshes/iiwa14/collision/link_4${collision_postfix}.stl"/>
        </geometry>
        <material name="Orange"/>
      </collision>
    </link>

    <!-- joint between link_4 and link_5 -->
    <joint name="joint_5" type="revolute">
      <parent link="link_4"/>
      <child link="link_5"/>
      <origin xyz="0 0.1845 0" rpy="${-PI / 2} ${PI} 0"/>
      <axis xyz="0 0 1"/>
      <limit lower="${-joint_limit_5 * PI / 180}" upper="${joint_limit_5 * PI / 180}" effort="${max_effort_5}" velocity="${max_velocity_5}" />
      <xacro:safe_controller safety="${safety}" lower="${-safety_percentage * joint_limit_5 * PI / 180}" upper="${safety_percentage * joint_limit_5 * PI / 180}" k_p="${safety_controller_k_pos}" k_v="${safety_controller_k_vel}"/>
      <dynamics damping="${joint_damping}"/>
    </joint>

    <link name="link_5">
      <inertial>
        <origin xyz="0.0001 0.021 0.076" rpy="0 0 0"/>
        <mass value="1.7"/>
        <inertia ixx="0.02" ixy="0" ixz="0" iyy="0.018" iyz="0" izz="0.005" />
      </inertial>

      <visual>
        <origin xyz="0 0 0" rpy="0 0 0"/>
        <geometry>
          <mesh filename="package://iiwa_description/meshes/iiwa14/visual/link_5.stl"/>
        </geometry>
        <material name="Orange"/>
      </visual>

      <collision>
        <origin xyz="0 0 0" rpy="0 0 0"/>
        <geometry>
          <mesh filename="package://iiwa_description/meshes/iiwa14/collision/link_5${collision_postfix}.stl"/>
        </geometry>
        <material name="Orange"/>
      </collision>
    </link>

    <!-- joint between link_5 and link_6 -->
    <joint name="joint_6" type="revolute">
      <parent link="link_5"/>
      <child link="link_6"/>
      <origin xyz="0 0 0.2155" rpy="${PI / 2} 0 0"/>
      <axis xyz="0 0 1"/>
      <limit lower="${-joint_limit_6 * PI / 180}" upper="${joint_limit_6 * PI / 180}" effort="${max_effort_6}" velocity="${max_velocity_6}" />
      <xacro:safe_controller safety="${safety}" lower="${-safety_percentage * joint_limit_6 * PI / 180}" upper="${safety_percentage * joint_limit_6 * PI / 180}" k_p="${safety_controller_k_pos}" k_v="${safety_controller_k_vel}"/>
      <dynamics damping="${joint_damping}"/>
    </joint>

    <link name="link_6">
      <inertial>
        <origin xyz="0 0.0006 0.0004" rpy="0 0 0"/>
        <mass value="1.8"/>
        <inertia ixx="0.005" ixy="0" ixz="0" iyy="0.0036" iyz="0" izz="0.0047" />
      </inertial>

      <visual>
        <origin xyz="0 0 0" rpy="0 0 0"/>
        <geometry>
          <mesh filename="package://iiwa_description/meshes/iiwa14/visual/link_6.stl"/>
        </geometry>
        <material name="Orange"/>
      </visual>

      <collision>
        <origin xyz="0 0 0" rpy="0 0 0"/>
        <geometry>
          <mesh filename="package://iiwa_description/meshes/iiwa14/collision/link_6${collision_postfix}.stl"/>
        </geometry>
        <material name="Orange"/>
      </collision>
    </link>

    <!-- joint between link_6 and link_7 -->
    <joint name="joint_7" type="revolute">
      <parent link="link_6"/>
      <child link="link_7"/>
      <origin xyz="0 0.081 0" rpy="${- PI / 2} ${PI} 0"/>
      <axis xyz="0 0 1"/>
      <limit lower="${-joint_limit_7 * PI / 180}" upper="${joint_limit_7 * PI / 180}" effort="${max_effort_7}" velocity="${max_velocity_7}" />
      <xacro:safe_controller safety="${safety}" lower="${-safety_percentage * joint_limit_7 * PI / 180}" upper="${safety_percentage * joint_limit_7 * PI / 180}" k_p="${safety_controller_k_pos}" k_v="${safety_controller_k_vel}"/>
      <dynamics damping="${joint_damping}"/>
    </joint>

    <link name="link_7">
      <inertial>
        <origin xyz="0 0 0.02" rpy="0 0 0"/>
        <mass value="0.3"/>
        <inertia ixx="0.001" ixy="0" ixz="0" iyy="0.001" iyz="0" izz="0.001" />
      </inertial>

      <visual>
        <origin xyz="0 0 0" rpy="0 0 0"/>
        <geometry>
          <mesh filename="package://iiwa_description/meshes/iiwa14/visual/link_7.stl"/>
        </geometry>
        <material name="Grey"/>
      </visual>

      <collision>
        <origin xyz="0 0 0" rpy="0 0 0"/>
        <geometry>
          <mesh filename="package://iiwa_description/meshes/iiwa14/collision/link_7${collision_postfix}.stl"/>
        </geometry>
        <material name="Grey"/>
      </collision>
    </link>

    <joint name="joint_ee" type="fixed">
      <parent link="link_7"/>
      <child link="link_ee"/>
      <origin xyz="0 0 0" rpy="0 0 0"/>
    </joint>

    <link name="link_ee">
      <inertial>
        <origin xyz="0 0 0" rpy="0 0 0"/>
        <mass value="1e-6"/>
        <inertia ixx="1" ixy="0" ixz="0" iyy="1" iyz="0" izz="1" />
      </inertial>
    </link>

    <xacro:if value="${force_sensor == True}">
      <xacro:force_torque_sensor parent_link_name="link_7" topic_name="FTS_topic" size_parent_link="0 0 0.045">
      </xacro:force_torque_sensor>
      <xacro:if value="${grabber == True}">
        <xacro:grabber parent_link_name="link_FTS" size_parent_link="0 0 0.0212">
        </xacro:grabber>
      </xacro:if>
    </xacro:if>
    <xacro:if value="${force_sensor == False}">
      <xacro:if value="${grabber == True}">
        <xacro:grabber parent_link_name="link_7" size_parent_link="0 0 0.045">
        </xacro:grabber>
      </xacro:if>
    </xacro:if>

    <!--Extensions -->
    <xacro:iiwa_gazebo />
    <xacro:iiwa_transmission hardware_interface="${hardware_interface}"/>

  </xacro:macro>

</robot>
